Workbook

Sheet Dashboard
A1: SALES & REVENUE ANALYSIS DASHBOARD
A3: Region | B3: All | D3: Category | E3: All | G3: Year | H3: All
A5: TOTAL REVENUE | D5: UNITS SOLD | G5: TOTAL ORDERS | J5: AVG REVENUE
A6: =IF($H$3="All",SUMIFS('Sales_Data'!$I$2:$I$181,'Sales_Data'!$C$2:$C$181,IF($B$3="All","*",$B$3),'Sales_Data'!$D$2:$D$181,IF($E$3="All","*",$E$3)),SUMIFS('Sales_Data'!$I$2:$I$181,'Sales_Data'!$C$2:$C$181,IF($B$3="All","*",$B$3),'Sales_Data'!$D$2:$D$181,IF($E$3="All","*",$E$3),'Sales_Data'!$K$2:$K$181,VALUE($H$3))) | D6: =IF($H$3="All",SUMIFS('Sales_Data'!$F$2:$F$181,'Sales_Data'!$C$2:$C$181,IF($B$3="All","*",$B$3),'Sales_Data'!$D$2:$D$181,IF($E$3="All","*",$E$3)),SUMIFS('Sales_Data'!$F$2:$F$181,'Sales_Data'!$C$2:$C$181,IF($B$3="All","*",$B$3),'Sales_Data'!$D$2:$D$181,IF($E$3="All","*",$E$3),'Sales_Data'!$K$2:$K$181,VALUE($H$3))) | G6: =IF($H$3="All",COUNTIFS('Sales_Data'!$C$2:$C$181,IF($B$3="All","*",$B$3),'Sales_Data'!$D$2:$D$181,IF($E$3="All","*",$E$3)),COUNTIFS('Sales_Data'!$C$2:$C$181,IF($B$3="All","*",$B$3),'Sales_Data'!$D$2:$D$181,IF($E$3="All","*",$E$3),'Sales_Data'!$K$2:$K$181,VALUE($H$3))) | J6: =IFERROR(A6/G6,0)
A9: Revenue by Region | D9: Revenue by Category | G9: Monthly Revenue | J9: Top 5 Products
A10: Central | B10: =IF($H$3="All",SUMIFS('Sales_Data'!$I$2:$I$181,'Sales_Data'!$C$2:$C$181,IF($B$3="All","*",$B$3),'Sales_Data'!$D$2:$D$181,IF($E$3="All","*",$E$3),'Sales_Data'!$C$2:$C$181,"Central"),SUMIFS('Sales_Data'!$I$2:$I$181,'Sales_Data'!$C$2:$C$181,IF($B$3="All","*",$B$3),'Sales_Data'!$D$2:$D$181,IF($E$3="All","*",$E$3),'Sales_Data'!$C$2:$C$181,"Central",'Sales_Data'!$K$2:$K$181,VALUE($H$3))) | D10: Accessories | E10: =IF($H$3="All",SUMIFS('Sales_Data'!$I$2:$I$181,'Sales_Data'!$C$2:$C$181,IF($B$3="All","*",$B$3),'Sales_Data'!$D$2:$D$181,IF($E$3="All","*",$E$3),'Sales_Data'!$D$2:$D$181,"Accessories"),SUMIFS('Sales_Data'!$I$2:$I$181,'Sales_Data'!$C$2:$C$181,IF($B$3="All","*",$B$3),'Sales_Data'!$D$2:$D$181,IF($E$3="All","*",$E$3),'Sales_Data'!$D$2:$D$181,"Accessories",'Sales_Data'!$K$2:$K$181,VALUE($H$3))) | G10: 2025-Jan | H10: =IF($H$3="All",SUMIFS('Sales_Data'!$I$2:$I$181,'Sales_Data'!$C$2:$C$181,IF($B$3="All","*",$B$3),'Sales_Data'!$D$2:$D$181,IF($E$3="All","*",$E$3),'Sales_Data'!$K$2:$K$181,2025,'Sales_Data'!$J$2:$J$181,"Jan"),SUMIFS('Sales_Data'!$I$2:$I$181,'Sales_Data'!$C$2:$C$181,IF($B$3="All","*",$B$3),'Sales_Data'!$D$2:$D$181,IF($E$3="All","*",$E$3),'Sales_Data'!$K$2:$K$181,2025,'Sales_Data'!$J$2:$J$181,"Jan",'Sales_Data'!$K$2:$K$181,VALUE($H$3))) | J10: Laptop | K10: =IF($H$3="All",SUMIFS('Sales_Data'!$I$2:$I$181,'Sales_Data'!$C$2:$C$181,IF($B$3="All","*",$B$3),'Sales_Data'!$D$2:$D$181,IF($E$3="All","*",$E$3),'Sales_Data'!$E$2:$E$181,"Laptop"),SUMIFS('Sales_Data'!$I$2:$I$181,'Sales_Data'!$C$2:$C$181,IF($B$3="All","*",$B$3),'Sales_Data'!$D$2:$D$181,IF($E$3="All","*",$E$3),'Sales_Data'!$E$2:$E$181,"Laptop",'Sales_Data'!$K$2:$K$181,VALUE($H$3)))
A11: East | B11: =IF($H$3="All",SUMIFS('Sales_Data'!$I$2:$I$181,'Sales_Data'!$C$2:$C$181,IF($B$3="All","*",$B$3),'Sales_Data'!$D$2:$D$181,IF($E$3="All","*",$E$3),'Sales_Data'!$C$2:$C$181,"East"),SUMIFS('Sales_Data'!$I$2:$I$181,'Sales_Data'!$C$2:$C$181,IF($B$3="All","*",$B$3),'Sales_Data'!$D$2:$D$181,IF($E$3="All","*",$E$3),'Sales_Data'!$C$2:$C$181,"East",'Sales_Data'!$K$2:$K$181,VALUE($H$3))) | D11: Electronics | E11: =IF($H$3="All",SUMIFS('Sales_Data'!$I$2:$I$181,'Sales_Data'!$C$2:$C$181,IF($B$3="All","*",$B$3),'Sales_Data'!$D$2:$D$181,IF($E$3="All","*",$E$3),'Sales_Data'!$D$2:$D$181,"Electronics"),SUMIFS('Sales_Data'!$I$2:$I$181,'Sales_Data'!$C$2:$C$181,IF($B$3="All","*",$B$3),'Sales_Data'!$D$2:$D$181,IF($E$3="All","*",$E$3),'Sales_Data'!$D$2:$D$181,"Electronics",'Sales_Data'!$K$2:$K$181,VALUE($H$3))) | G11: 2025-Feb | H11: =IF($H$3="All",SUMIFS('Sales_Data'!$I$2:$I$181,'Sales_Data'!$C$2:$C$181,IF($B$3="All","*",$B$3),'Sales_Data'!$D$2:$D$181,IF($E$3="All","*",$E$3),'Sales_Data'!$K$2:$K$181,2025,'Sales_Data'!$J$2:$J$181,"Feb"),SUMIFS('Sales_Data'!$I$2:$I$181,'Sales_Data'!$C$2:$C$181,IF($B$3="All","*",$B$3),'Sales_Data'!$D$2:$D$181,IF($E$3="All","*",$E$3),'Sales_Data'!$K$2:$K$181,2025,'Sales_Data'!$J$2:$J$181,"Feb",'Sales_Data'!$K$2:$K$181,VALUE($H$3))) | J11: Smartphone | K11: =IF($H$3="All",SUMIFS('Sales_Data'!$I$2:$I$181,'Sales_Data'!$C$2:$C$181,IF($B$3="All","*",$B$3),'Sales_Data'!$D$2:$D$181,IF($E$3="All","*",$E$3),'Sales_Data'!$E$2:$E$181,"Smartphone"),SUMIFS('Sales_Data'!$I$2:$I$181,'Sales_Data'!$C$2:$C$181,IF($B$3="All","*",$B$3),'Sales_Data'!$D$2:$D$181,IF($E$3="All","*",$E$3),'Sales_Data'!$E$2:$E$181,"Smartphone",'Sales_Data'!$K$2:$K$181,VALUE($H$3)))
A12: North | B12: =IF($H$3="All",SUMIFS('Sales_Data'!$I$2:$I$181,'Sales_Data'!$C$2:$C$181,IF($B$3="All","*",$B$3),'Sales_Data'!$D$2:$D$181,IF($E$3="All","*",$E$3),'Sales_Data'!$C$2:$C$181,"North"),SUMIFS('Sales_Data'!$I$2:$I$181,'Sales_Data'!$C$2:$C$181,IF($B$3="All","*",$B$3),'Sales_Data'!$D$2:$D$181,IF($E$3="All","*",$E$3),'Sales_Data'!$C$2:$C$181,"North",'Sales_Data'!$K$2:$K$181,VALUE($H$3))) | D12: Furniture | E12: =IF($H$3="All",SUMIFS('Sales_Data'!$I$2:$I$181,'Sales_Data'!$C$2:$C$181,IF($B$3="All","*",$B$3),'Sales_Data'!$D$2:$D$181,IF($E$3="All","*",$E$3),'Sales_Data'!$D$2:$D$181,"Furniture"),SUMIFS('Sales_Data'!$I$2:$I$181,'Sales_Data'!$C$2:$C$181,IF($B$3="All","*",$B$3),'Sales_Data'!$D$2:$D$181,IF($E$3="All","*",$E$3),'Sales_Data'!$D$2:$D$181,"Furniture",'Sales_Data'!$K$2:$K$181,VALUE($H$3))) | G12: 2025-Mar | H12: =IF($H$3="All",SUMIFS('Sales_Data'!$I$2:$I$181,'Sales_Data'!$C$2:$C$181,IF($B$3="All","*",$B$3),'Sales_Data'!$D$2:$D$181,IF($E$3="All","*",$E$3),'Sales_Data'!$K$2:$K$181,2025,'Sales_Data'!$J$2:$J$181,"Mar"),SUMIFS('Sales_Data'!$I$2:$I$181,'Sales_Data'!$C$2:$C$181,IF($B$3="All","*",$B$3),'Sales_Data'!$D$2:$D$181,IF($E$3="All","*",$E$3),'Sales_Data'!$K$2:$K$181,2025,'Sales_Data'!$J$2:$J$181,"Mar",'Sales_Data'!$K$2:$K$181,VALUE($H$3))) | J12: Monitor | K12: =IF($H$3="All",SUMIFS('Sales_Data'!$I$2:$I$181,'Sales_Data'!$C$2:$C$181,IF($B$3="All","*",$B$3),'Sales_Data'!$D$2:$D$181,IF($E$3="All","*",$E$3),'Sales_Data'!$E$2:$E$181,"Monitor"),SUMIFS('Sales_Data'!$I$2:$I$181,'Sales_Data'!$C$2:$C$181,IF($B$3="All","*",$B$3),'Sales_Data'!$D$2:$D$181,IF($E$3="All","*",$E$3),'Sales_Data'!$E$2:$E$181,"Monitor",'Sales_Data'!$K$2:$K$181,VALUE($H$3)))
A13: South | B13: =IF($H$3="All",SUMIFS('Sales_Data'!$I$2:$I$181,'Sales_Data'!$C$2:$C$181,IF($B$3="All","*",$B$3),'Sales_Data'!$D$2:$D$181,IF($E$3="All","*",$E$3),'Sales_Data'!$C$2:$C$181,"South"),SUMIFS('Sales_Data'!$I$2:$I$181,'Sales_Data'!$C$2:$C$181,IF($B$3="All","*",$B$3),'Sales_Data'!$D$2:$D$181,IF($E$3="All","*",$E$3),'Sales_Data'!$C$2:$C$181,"South",'Sales_Data'!$K$2:$K$181,VALUE($H$3))) | D13: Office Equipment | E13: =IF($H$3="All",SUMIFS('Sales_Data'!$I$2:$I$181,'Sales_Data'!$C$2:$C$181,IF($B$3="All","*",$B$3),'Sales_Data'!$D$2:$D$181,IF($E$3="All","*",$E$3),'Sales_Data'!$D$2:$D$181,"Office Equipment"),SUMIFS('Sales_Data'!$I$2:$I$181,'Sales_Data'!$C$2:$C$181,IF($B$3="All","*",$B$3),'Sales_Data'!$D$2:$D$181,IF($E$3="All","*",$E$3),'Sales_Data'!$D$2:$D$181,"Office Equipment",'Sales_Data'!$K$2:$K$181,VALUE($H$3))) | G13: 2025-Apr | H13: =IF($H$3="All",SUMIFS('Sales_Data'!$I$2:$I$181,'Sales_Data'!$C$2:$C$181,IF($B$3="All","*",$B$3),'Sales_Data'!$D$2:$D$181,IF($E$3="All","*",$E$3),'Sales_Data'!$K$2:$K$181,2025,'Sales_Data'!$J$2:$J$181,"Apr"),SUMIFS('Sales_Data'!$I$2:$I$181,'Sales_Data'!$C$2:$C$181,IF($B$3="All","*",$B$3),'Sales_Data'!$D$2:$D$181,IF($E$3="All","*",$E$3),'Sales_Data'!$K$2:$K$181,2025,'Sales_Data'!$J$2:$J$181,"Apr",'Sales_Data'!$K$2:$K$181,VALUE($H$3))) | J13: Desk | K13: =IF($H$3="All",SUMIFS('Sales_Data'!$I$2:$I$181,'Sales_Data'!$C$2:$C$181,IF($B$3="All","*",$B$3),'Sales_Data'!$D$2:$D$181,IF($E$3="All","*",$E$3),'Sales_Data'!$E$2:$E$181,"Desk"),SUMIFS('Sales_Data'!$I$2:$I$181,'Sales_Data'!$C$2:$C$181,IF($B$3="All","*",$B$3),'Sales_Data'!$D$2:$D$181,IF($E$3="All","*",$E$3),'Sales_Data'!$E$2:$E$181,"Desk",'Sales_Data'!$K$2:$K$181,VALUE($H$3)))
A14: West | B14: =IF($H$3="All",SUMIFS('Sales_Data'!$I$2:$I$181,'Sales_Data'!$C$2:$C$181,IF($B$3="All","*",$B$3),'Sales_Data'!$D$2:$D$181,IF($E$3="All","*",$E$3),'Sales_Data'!$C$2:$C$181,"West"),SUMIFS('Sales_Data'!$I$2:$I$181,'Sales_Data'!$C$2:$C$181,IF($B$3="All","*",$B$3),'Sales_Data'!$D$2:$D$181,IF($E$3="All","*",$E$3),'Sales_Data'!$C$2:$C$181,"West",'Sales_Data'!$K$2:$K$181,VALUE($H$3))) | G14: 2025-May | H14: =IF($H$3="All",SUMIFS('Sales_Data'!$I$2:$I$181,'Sales_Data'!$C$2:$C$181,IF($B$3="All","*",$B$3),'Sales_Data'!$D$2:$D$181,IF($E$3="All","*",$E$3),'Sales_Data'!$K$2:$K$181,2025,'Sales_Data'!$J$2:$J$181,"May"),SUMIFS('Sales_Data'!$I$2:$I$181,'Sales_Data'!$C$2:$C$181,IF($B$3="All","*",$B$3),'Sales_Data'!$D$2:$D$181,IF($E$3="All","*",$E$3),'Sales_Data'!$K$2:$K$181,2025,'Sales_Data'!$J$2:$J$181,"May",'Sales_Data'!$K$2:$K$181,VALUE($H$3))) | J14: Printer | K14: =IF($H$3="All",SUMIFS('Sales_Data'!$I$2:$I$181,'Sales_Data'!$C$2:$C$181,IF($B$3="All","*",$B$3),'Sales_Data'!$D$2:$D$181,IF($E$3="All","*",$E$3),'Sales_Data'!$E$2:$E$181,"Printer"),SUMIFS('Sales_Data'!$I$2:$I$181,'Sales_Data'!$C$2:$C$181,IF($B$3="All","*",$B$3),'Sales_Data'!$D$2:$D$181,IF($E$3="All","*",$E$3),'Sales_Data'!$E$2:$E$181,"Printer",'Sales_Data'!$K$2:$K$181,VALUE($H$3)))
G15: 2025-Jun | H15: =IF($H$3="All",SUMIFS('Sales_Data'!$I$2:$I$181,'Sales_Data'!$C$2:$C$181,IF($B$3="All","*",$B$3),'Sales_Data'!$D$2:$D$181,IF($E$3="All","*",$E$3),'Sales_Data'!$K$2:$K$181,2025,'Sales_Data'!$J$2:$J$181,"Jun"),SUMIFS('Sales_Data'!$I$2:$I$181,'Sales_Data'!$C$2:$C$181,IF($B$3="All","*",$B$3),'Sales_Data'!$D$2:$D$181,IF($E$3="All","*",$E$3),'Sales_Data'!$K$2:$K$181,2025,'Sales_Data'!$J$2:$J$181,"Jun",'Sales_Data'!$K$2:$K$181,VALUE($H$3)))
G16: 2025-Jul | H16: =IF($H$3="All",SUMIFS('Sales_Data'!$I$2:$I$181,'Sales_Data'!$C$2:$C$181,IF($B$3="All","*",$B$3),'Sales_Data'!$D$2:$D$181,IF($E$3="All","*",$E$3),'Sales_Data'!$K$2:$K$181,2025,'Sales_Data'!$J$2:$J$181,"Jul"),SUMIFS('Sales_Data'!$I$2:$I$181,'Sales_Data'!$C$2:$C$181,IF($B$3="All","*",$B$3),'Sales_Data'!$D$2:$D$181,IF($E$3="All","*",$E$3),'Sales_Data'!$K$2:$K$181,2025,'Sales_Data'!$J$2:$J$181,"Jul",'Sales_Data'!$K$2:$K$181,VALUE($H$3)))
G17: 2025-Aug | H17: =IF($H$3="All",SUMIFS('Sales_Data'!$I$2:$I$181,'Sales_Data'!$C$2:$C$181,IF($B$3="All","*",$B$3),'Sales_Data'!$D$2:$D$181,IF($E$3="All","*",$E$3),'Sales_Data'!$K$2:$K$181,2025,'Sales_Data'!$J$2:$J$181,"Aug"),SUMIFS('Sales_Data'!$I$2:$I$181,'Sales_Data'!$C$2:$C$181,IF($B$3="All","*",$B$3),'Sales_Data'!$D$2:$D$181,IF($E$3="All","*",$E$3),'Sales_Data'!$K$2:$K$181,2025,'Sales_Data'!$J$2:$J$181,"Aug",'Sales_Data'!$K$2:$K$181,VALUE($H$3)))
G18: 2025-Sep | H18: =IF($H$3="All",SUMIFS('Sales_Data'!$I$2:$I$181,'Sales_Data'!$C$2:$C$181,IF($B$3="All","*",$B$3),'Sales_Data'!$D$2:$D$181,IF($E$3="All","*",$E$3),'Sales_Data'!$K$2:$K$181,2025,'Sales_Data'!$J$2:$J$181,"Sep"),SUMIFS('Sales_Data'!$I$2:$I$181,'Sales_Data'!$C$2:$C$181,IF($B$3="All","*",$B$3),'Sales_Data'!$D$2:$D$181,IF($E$3="All","*",$E$3),'Sales_Data'!$K$2:$K$181,2025,'Sales_Data'!$J$2:$J$181,"Sep",'Sales_Data'!$K$2:$K$181,VALUE($H$3)))
G19: 2025-Oct | H19: =IF($H$3="All",SUMIFS('Sales_Data'!$I$2:$I$181,'Sales_Data'!$C$2:$C$181,IF($B$3="All","*",$B$3),'Sales_Data'!$D$2:$D$181,IF($E$3="All","*",$E$3),'Sales_Data'!$K$2:$K$181,2025,'Sales_Data'!$J$2:$J$181,"Oct"),SUMIFS('Sales_Data'!$I$2:$I$181,'Sales_Data'!$C$2:$C$181,IF($B$3="All","*",$B$3),'Sales_Data'!$D$2:$D$181,IF($E$3="All","*",$E$3),'Sales_Data'!$K$2:$K$181,2025,'Sales_Data'!$J$2:$J$181,"Oct",'Sales_Data'!$K$2:$K$181,VALUE($H$3)))
G20: 2025-Nov | H20: =IF($H$3="All",SUMIFS('Sales_Data'!$I$2:$I$181,'Sales_Data'!$C$2:$C$181,IF($B$3="All","*",$B$3),'Sales_Data'!$D$2:$D$181,IF($E$3="All","*",$E$3),'Sales_Data'!$K$2:$K$181,2025,'Sales_Data'!$J$2:$J$181,"Nov"),SUMIFS('Sales_Data'!$I$2:$I$181,'Sales_Data'!$C$2:$C$181,IF($B$3="All","*",$B$3),'Sales_Data'!$D$2:$D$181,IF($E$3="All","*",$E$3),'Sales_Data'!$K$2:$K$181,2025,'Sales_Data'!$J$2:$J$181,"Nov",'Sales_Data'!$K$2:$K$181,VALUE($H$3)))
G21: 2025-Dec | H21: =IF($H$3="All",SUMIFS('Sales_Data'!$I$2:$I$181,'Sales_Data'!$C$2:$C$181,IF($B$3="All","*",$B$3),'Sales_Data'!$D$2:$D$181,IF($E$3="All","*",$E$3),'Sales_Data'!$K$2:$K$181,2025,'Sales_Data'!$J$2:$J$181,"Dec"),SUMIFS('Sales_Data'!$I$2:$I$181,'Sales_Data'!$C$2:$C$181,IF($B$3="All","*",$B$3),'Sales_Data'!$D$2:$D$181,IF($E$3="All","*",$E$3),'Sales_Data'!$K$2:$K$181,2025,'Sales_Data'!$J$2:$J$181,"Dec",'Sales_Data'!$K$2:$K$181,VALUE($H$3)))
G22: 2026-Jan | H22: =IF($H$3="All",SUMIFS('Sales_Data'!$I$2:$I$181,'Sales_Data'!$C$2:$C$181,IF($B$3="All","*",$B$3),'Sales_Data'!$D$2:$D$181,IF($E$3="All","*",$E$3),'Sales_Data'!$K$2:$K$181,2026,'Sales_Data'!$J$2:$J$181,"Jan"),SUMIFS('Sales_Data'!$I$2:$I$181,'Sales_Data'!$C$2:$C$181,IF($B$3="All","*",$B$3),'Sales_Data'!$D$2:$D$181,IF($E$3="All","*",$E$3),'Sales_Data'!$K$2:$K$181,2026,'Sales_Data'!$J$2:$J$181,"Jan",'Sales_Data'!$K$2:$K$181,VALUE($H$3)))
G23: 2026-Feb | H23: =IF($H$3="All",SUMIFS('Sales_Data'!$I$2:$I$181,'Sales_Data'!$C$2:$C$181,IF($B$3="All","*",$B$3),'Sales_Data'!$D$2:$D$181,IF($E$3="All","*",$E$3),'Sales_Data'!$K$2:$K$181,2026,'Sales_Data'!$J$2:$J$181,"Feb"),SUMIFS('Sales_Data'!$I$2:$I$181,'Sales_Data'!$C$2:$C$181,IF($B$3="All","*",$B$3),'Sales_Data'!$D$2:$D$181,IF($E$3="All","*",$E$3),'Sales_Data'!$K$2:$K$181,2026,'Sales_Data'!$J$2:$J$181,"Feb",'Sales_Data'!$K$2:$K$181,VALUE($H$3)))
G24: 2026-Mar | H24: =IF($H$3="All",SUMIFS('Sales_Data'!$I$2:$I$181,'Sales_Data'!$C$2:$C$181,IF($B$3="All","*",$B$3),'Sales_Data'!$D$2:$D$181,IF($E$3="All","*",$E$3),'Sales_Data'!$K$2:$K$181,2026,'Sales_Data'!$J$2:$J$181,"Mar"),SUMIFS('Sales_Data'!$I$2:$I$181,'Sales_Data'!$C$2:$C$181,IF($B$3="All","*",$B$3),'Sales_Data'!$D$2:$D$181,IF($E$3="All","*",$E$3),'Sales_Data'!$K$2:$K$181,2026,'Sales_Data'!$J$2:$J$181,"Mar",'Sales_Data'!$K$2:$K$181,VALUE($H$3)))
G25: 2026-Apr | H25: =IF($H$3="All",SUMIFS('Sales_Data'!$I$2:$I$181,'Sales_Data'!$C$2:$C$181,IF($B$3="All","*",$B$3),'Sales_Data'!$D$2:$D$181,IF($E$3="All","*",$E$3),'Sales_Data'!$K$2:$K$181,2026,'Sales_Data'!$J$2:$J$181,"Apr"),SUMIFS('Sales_Data'!$I$2:$I$181,'Sales_Data'!$C$2:$C$181,IF($B$3="All","*",$B$3),'Sales_Data'!$D$2:$D$181,IF($E$3="All","*",$E$3),'Sales_Data'!$K$2:$K$181,2026,'Sales_Data'!$J$2:$J$181,"Apr",'Sales_Data'!$K$2:$K$181,VALUE($H$3)))
G26: 2026-May | H26: =IF($H$3="All",SUMIFS('Sales_Data'!$I$2:$I$181,'Sales_Data'!$C$2:$C$181,IF($B$3="All","*",$B$3),'Sales_Data'!$D$2:$D$181,IF($E$3="All","*",$E$3),'Sales_Data'!$K$2:$K$181,2026,'Sales_Data'!$J$2:$J$181,"May"),SUMIFS('Sales_Data'!$I$2:$I$181,'Sales_Data'!$C$2:$C$181,IF($B$3="All","*",$B$3),'Sales_Data'!$D$2:$D$181,IF($E$3="All","*",$E$3),'Sales_Data'!$K$2:$K$181,2026,'Sales_Data'!$J$2:$J$181,"May",'Sales_Data'!$K$2:$K$181,VALUE($H$3)))
G27: 2026-Jun | H27: =IF($H$3="All",SUMIFS('Sales_Data'!$I$2:$I$181,'Sales_Data'!$C$2:$C$181,IF($B$3="All","*",$B$3),'Sales_Data'!$D$2:$D$181,IF($E$3="All","*",$E$3),'Sales_Data'!$K$2:$K$181,2026,'Sales_Data'!$J$2:$J$181,"Jun"),SUMIFS('Sales_Data'!$I$2:$I$181,'Sales_Data'!$C$2:$C$181,IF($B$3="All","*",$B$3),'Sales_Data'!$D$2:$D$181,IF($E$3="All","*",$E$3),'Sales_Data'!$K$2:$K$181,2026,'Sales_Data'!$J$2:$J$181,"Jun",'Sales_Data'!$K$2:$K$181,VALUE($H$3)))
G28: 2026-Jul | H28: =IF($H$3="All",SUMIFS('Sales_Data'!$I$2:$I$181,'Sales_Data'!$C$2:$C$181,IF($B$3="All","*",$B$3),'Sales_Data'!$D$2:$D$181,IF($E$3="All","*",$E$3),'Sales_Data'!$K$2:$K$181,2026,'Sales_Data'!$J$2:$J$181,"Jul"),SUMIFS('Sales_Data'!$I$2:$I$181,'Sales_Data'!$C$2:$C$181,IF($B$3="All","*",$B$3),'Sales_Data'!$D$2:$D$181,IF($E$3="All","*",$E$3),'Sales_Data'!$K$2:$K$181,2026,'Sales_Data'!$J$2:$J$181,"Jul",'Sales_Data'!$K$2:$K$181,VALUE($H$3)))
G29: 2026-Aug | H29: =IF($H$3="All",SUMIFS('Sales_Data'!$I$2:$I$181,'Sales_Data'!$C$2:$C$181,IF($B$3="All","*",$B$3),'Sales_Data'!$D$2:$D$181,IF($E$3="All","*",$E$3),'Sales_Data'!$K$2:$K$181,2026,'Sales_Data'!$J$2:$J$181,"Aug"),SUMIFS('Sales_Data'!$I$2:$I$181,'Sales_Data'!$C$2:$C$181,IF($B$3="All","*",$B$3),'Sales_Data'!$D$2:$D$181,IF($E$3="All","*",$E$3),'Sales_Data'!$K$2:$K$181,2026,'Sales_Data'!$J$2:$J$181,"Aug",'Sales_Data'!$K$2:$K$181,VALUE($H$3)))
G30: 2026-Sep | H30: =IF($H$3="All",SUMIFS('Sales_Data'!$I$2:$I$181,'Sales_Data'!$C$2:$C$181,IF($B$3="All","*",$B$3),'Sales_Data'!$D$2:$D$181,IF($E$3="All","*",$E$3),'Sales_Data'!$K$2:$K$181,2026,'Sales_Data'!$J$2:$J$181,"Sep"),SUMIFS('Sales_Data'!$I$2:$I$181,'Sales_Data'!$C$2:$C$181,IF($B$3="All","*",$B$3),'Sales_Data'!$D$2:$D$181,IF($E$3="All","*",$E$3),'Sales_Data'!$K$2:$K$181,2026,'Sales_Data'!$J$2:$J$181,"Sep",'Sales_Data'!$K$2:$K$181,VALUE($H$3)))
H32: KEY INSIGHTS 1. Highest revenue region: West — ₹5,925,793.15. 2. Lowest revenue region: South — ₹3,294,850.20. 3. Highest revenue category: Electronics — ₹18,560,168.61. 4. Top revenue-generating product: Laptop — ₹9,136,020.16. 5. Monthly revenue fluctuates considerably. Highest: May 2025 — ₹2,335,952.54. Lowest: August 2025 — ₹514,754.86.
A65: Prepared for Internship Submission | Jagan Mohan Reddy

Sheet Sales_Data
A1: Order ID | B1: Order Date | C1: Region | D1: Category | E1: Product | F1: Units Sold | G1: Unit Price | H1: Discount | I1: Revenue | J1: Month | K1: Year
A2: ORD-1001 | B2: 45658 | C2: West | D2: Furniture | E2: Desk | F2: 13 | G2: 12671.26 | H2: 0.05 | I2: 156490.06 | J2: Jan | K2: 2025
A3: ORD-1002 | B3: 45661 | C3: South | D3: Accessories | E3: Keyboard | F3: 3 | G3: 1785.33 | H3: 0.05 | I3: 5088.19 | J3: Jan | K3: 2025
A4: ORD-1003 | B4: 45665 | C4: West | D4: Accessories | E4: Keyboard | F4: 8 | G4: 1627.41 | H4: 0.05 | I4: 12368.32 | J4: Jan | K4: 2025
A5: ORD-1004 | B5: 45668 | C5: West | D5: Electronics | E5: Smartphone | F5: 14 | G5: 26218.22 | H5: 0.03 | I5: 356043.43 | J5: Jan | K5: 2025
A6: ORD-1005 | B6: 45672 | C6: North | D6: Accessories | E6: Keyboard | F6: 12 | G6: 1808.91 | H6: 0.03 | I6: 21055.71 | J6: Jan | K6: 2025
A7: ORD-1006 | B7: 45675 | C7: North | D7: Electronics | E7: Monitor | F7: 1 | G7: 18402.67 | H7: 0.05 | I7: 17482.54 | J7: Jan | K7: 2025
A8: ORD-1007 | B8: 45679 | C8: West | D8: Electronics | E8: Smartphone | F8: 12 | G8: 27341.79 | H8: 0.05 | I8: 311696.41 | J8: Jan | K8: 2025
A9: ORD-1008 | B9: 45682 | C9: North | D9: Electronics | E9: Monitor | F9: 3 | G9: 18387.16 | H9: 0.1 | I9: 49645.33 | J9: Jan | K9: 2025
A10: ORD-1009 | B10: 45686 | C10: North | D10: Accessories | E10: Keyboard | F10: 7 | G10: 1961.6 | H10: 0.03 | I10: 13319.26 | J10: Jan | K10: 2025
A11: ORD-1010 | B11: 45690 | C11: South | D11: Electronics | E11: Monitor | F11: 10 | G11: 16257.48 | H11: 0 | I11: 162574.8 | J11: Feb | K11: 2025
A12: ORD-1011 | B12: 45693 | C12: West | D12: Electronics | E12: Smartphone | F12: 12 | G12: 25883.41 | H12: 0.08 | I12: 285752.85 | J12: Feb | K12: 2025
A13: ORD-1012 | B13: 45697 | C13: East | D13: Accessories | E13: Keyboard | F13: 14 | G13: 1713.16 | H13: 0 | I13: 23984.24 | J13: Feb | K13: 2025
... A181: ORD-1180 | B181: 46295 | C181: West | D181: Accessories | E181: Keyboard | F181: 10 | G181: 1707.97 | H181: 0.03 | I181: 16567.31 | J181: Sep | K181: 2026

Sheet Analysis
A1: SALES & REVENUE ANALYSIS — ANALYSIS
A3: DATA QUALITY CHECKS | E3: FILTER LISTS
A4: Rows | B4: 180 | E4: Region | F4: Category | G4: Year
A5: Columns | B5: 11 | E5: All | F5: All | G5: All
A6: Missing values | B6: 0 | E6: Central | F6: Accessories | G6: 2025
A7: Duplicate Order IDs | B7: 0 | E7: East | F7: Electronics | G7: 2026
A8: Invalid/missing dates | B8: 0 | E8: North | F8: Furniture
A9: Negative Units Sold | B9: 0 | E9: South | F9: Office Equipment
A10: Non-positive Unit Price | B10: 0 | E10: West
A11: Discount outside 0–100% | B11: 0
A12: Negative Revenue | B12: 0
A13: Revenue formula differences > ₹0.05 | B13: 0
A16: KPI / SUMMARY METRICS
A17: Total Revenue | B17: 25099726
A18: Total Units Sold | B18: 1437
A19: Total Orders | B19: 180
A20: Average Revenue | B20: 139442.92
A27: Revenue by Region
A28: Item | B28: Revenue
A29: West | B29: 5925793.2
A30: North | B30: 5525115.6
A31: East | B31: 5258667.4
A32: Central | B32: 5095300
A33: South | B33: 3294850.2
A36: Revenue by Category
A37: Item | B37: Revenue
A38: Electronics | B38: 18560169
A39: Furniture | B39: 3848879
A40: Office Equipment | B40: 1989694
A41: Accessories | B41: 700984.77
A44: Revenue by Product
A45: Item | B45: Revenue
A46: Laptop | B46: 9136020.2
A47: Smartphone | B47: 6101282.4
A48: Monitor | B48: 3322866
A49: Desk | B49: 2084935.3
A50: Printer | B50: 1989694
A51: Office Chair | B51: 1763943.7
A52: Keyboard | B52: 432748.35
A53: Headphones | B53: 268236.42
...
